<?xml version="1.0"?>
<robot xmlns:xacro="http://www.ros.org/wiki/xacro">

  <!-- Generic link definition -->
  <xacro:macro name="mechanism_link" params="name mesh mass ixx iyy izz">
    <link name="${name}">
      <visual>
        <geometry>
          <mesh filename="package://drone_description/meshes/${mesh}" scale="1 1 1"/>
        </geometry>
      </visual>
      <collision>
        <geometry>
          <mesh filename="package://drone_description/meshes/${mesh}" scale="1 1 1"/>
        </geometry>
      </collision>
      <inertial>
        <origin xyz="0 0 0" rpy="0 0 0"/>
        <mass value="${mass}"/>
        <inertia ixx="${ixx}" iyy="${iyy}" izz="${izz}" ixy="0.0" ixz="0.0" iyz="0.0"/>
      </inertial>
    </link>
  </xacro:macro> 

  <xacro:macro name="arm_brace_pair" params="prefix index parent">
    <!-- Arm link -->
    <link name="${prefix}_arm_${index}">
      <visual>
        <geometry>
          <mesh filename="package://drone_description/meshes/arm_${index}.dae"/>
        </geometry>
      </visual>
      <collision>
        <geometry>
          <mesh filename="package://drone_description/meshes/arm_${index}.dae"/>
        </geometry>
      </collision>
      <inertial>
        <origin xyz="0 0 0" rpy="0 0 0"/>
        <mass value="0.2"/>
        <inertia ixx="0.00012" iyy="0.00012" izz="0.00004" ixy="0.0" ixz="0.0" iyz="0.0"/>
      </inertial>
    </link>

    <gazebo reference="${prefix}_arm_${index}"><material>Gazebo/DarkGrey</material></gazebo>

    <link name="${prefix}_arm_${index}_dummy"/> 

    <!-- Dummy joint to allow reuse of braces across arms -->
    <joint name="${prefix}arm_${index}_dummy_to_arm_${index}_joint" type="fixed">
      <parent link="${prefix}_arm_${index}_dummy"/>
      <child link="${prefix}_arm_${index}"/>
      <origin xyz="0 0 0" rpy="0 0 0"/>
    </joint>

    <!-- Brace link -->
    <link name="${prefix}_brace_${index}">
      <visual>
        <geometry>
          <mesh filename="package://drone_description/meshes/brace_${index}.dae"/>
        </geometry>
      </visual>
      <collision>
        <geometry>
          <mesh filename="package://drone_description/meshes/brace_${index}.dae"/>
        </geometry>
      </collision>
      <inertial>
        <origin xyz="0 0 0" rpy="0 0 0"/>
        <mass value="0.15"/>
        <inertia ixx="0.00007" iyy="0.00007" izz="0.00003" ixy="0.0" ixz="0.0" iyz="0.0"/>
      </inertial>
    </link>

    <gazebo reference="${prefix}_brace_${index}"><material>Gazebo/DarkGrey</material></gazebo>

    <!-- Revolute joint between slider and brace -->
    <joint name="${prefix}slider_to_brace_${index}_joint" type="revolute">
      <parent link="${parent}"/>
      <child link="${prefix}_brace_${index}"/>
      <origin xyz="0 0 0" rpy="0 0 0"/>
      <axis xyz="0 0 1"/>
      <limit lower="-1.57" upper="1.57" effort="1.0" velocity="1.0"/>
      <dynamics damping="0.01" friction="0.02"/>
    </joint>

    <!-- Revolute joint between brace and dummy arm link -->
    <joint name="${prefix}brace_${index}_to_arm_${index}_dummy_joint" type="revolute">
      <parent link="${prefix}_brace_${index}"/>
      <child link="${prefix}_arm_${index}_dummy"/>
      <origin xyz="0 0 0" rpy="0 0 0"/>
      <axis xyz="0 0 1"/>
      <limit lower="-1.57" upper="1.57" effort="1.0" velocity="1.0"/>
      <dynamics damping="0.01" friction="0.02"/>
    </joint>

  </xacro:macro>

</robot>
